Workbook

Sheet Coil summary
A1: Final magnetometer coils - Once coil is wound, measure L and R and do recalculations!!
A2: Characteristic | B2: Polarization | C2: Sensing / coil | D2: Unit
A3: Physical build and electrical resistance
A4: Spool wire length | B4: ='Inputs and method'!B5*0.3048 -> 153.924 | C4: ='Inputs and method'!C5*0.3048 -> 384.9624 | D4: m
A5: Usable wire length | B5: =B4*(1-'Inputs and method'!B12) -> 149.30628 | C5: =C4*(1-'Inputs and method'!C12) -> 373.41353 | D5: m
A6: Design wire OD | B6: ='Inputs and method'!B6 -> 0.714 | C6: ='Inputs and method'!C6 -> 0.462 | D6: mm
A7: Bobbin outer dimensions | B7: 146 × 76 | C7: 60 × 60 | D7: mm
A8: Bobbin inner dimensions | B8: 140 × 70 | C8: 56 × 56 | D8: mm
A9: Turns per complete layer | B9: =INT('Inputs and method'!B11/B6) -> 140 | C9: =INT('Inputs and method'!C11/C6) -> 216 | D9: turns
A10: First-layer turn perimeter | B10: =2*('Inputs and method'!B7+'Inputs and method'!B8+2*B6)/1000 -> 0.446856 | C10: =2*('Inputs and method'!C7+'Inputs and method'!C8+2*C6)/1000 -> 0.241848 | D10: m
A11: Perimeter added per layer | B11: =8*B6/1000 -> 0.005712 | C11: =8*C6/1000 -> 0.003696 | D11: m
A12: Wire in complete layers | B12: =B9*('Inputs and method'!B14*B10+B11*'Inputs and method'!B14*('Inputs and method'!B14-1)/2) -> 125.91936 | C12: =C9*('Inputs and method'!C14*C10+C11*'Inputs and method'!C14*('Inputs and method'!C14-1)/2) -> 325.41005 | D12: m
A13: Next-layer turn perimeter | B13: =B10+'Inputs and method'!B14*B11 -> 0.45828 | C13: =C10+'Inputs and method'!C14*C11 -> 0.264024 | D13: m
A14: Turns in partial final layer | B14: =MAX(0,MIN(B9,INT((B5-B12)/B13))) -> 51 | C14: =MAX(0,MIN(C9,INT((C5-C12)/C13))) -> 181 | D14: turns
A15: Estimated total turns | B15: ='Inputs and method'!B14*B9+B14 -> 331 | C15: ='Inputs and method'!C14*C9+C14 -> 1477 | D15: turns
A16: Occupied layers | B16: ='Inputs and method'!B14+IF(B14>0,1,0) -> 3 | C16: ='Inputs and method'!C14+IF(C14>0,1,0) -> 7 | D16: layers
A17: Wire used in winding | B17: =B12+B14*B13 -> 149.29164 | C17: =C12+C14*C13 -> 373.19839 | D17: m
A18: Wire left on spool | B18: =B4-B17 -> 4.63236 | C18: =C4-C17 -> 11.764008 | D18: m
A19: Estimated DC resistance at 20 °C | B19: =B17/0.3048/1000*'Inputs and method'!B13 -> 7.9054038 | C19: =C17/0.3048/1000*'Inputs and method'!C13 -> 49.967934 | D19: Ω
A21: Polarization coil • predicted operation
A22: Operating current | B22: =MIN('Inputs and method'!B15,'Inputs and method'!B16/B19) -> 3 | D22: A
A23: Applied coil voltage | B23: =B22*B19 -> 23.716211 | D23: V
A24: Resistive power while on | B24: =B22^2*B19 -> 71.148634 | D24: W
A25: Ampere-turns | B25: =B15*B22 -> 993 | D25: A·turn
A26: Estimated center field | B26: ='Inputs and method'!B25*(B25/('Inputs and method'!B24*3)) -> 8.6330994 | D26: mT
A27: Estimated inductance | B27: ='Inputs and method'!B26*(B15/'Inputs and method'!B24)^2 -> 9.8354237 | D27: mH
A28: Stored magnetic energy | B28: =B27*B22^2/2 -> 44.259407 | D28: mJ
A29: L/R turn-on time constant | B29: =B27/B19 -> 1.2441393 | D29: ms
A30: Approximate TVS turn-off time | B30: =B29*LN(1+B22*B19/'Inputs and method'!B17) -> 0.37223584 | D30: ms
A32: Sensing coils • predicted receive behavior
A33: Estimated inductance per coil | C33: =0.8*(SQRT((('Inputs and method'!C7+C6*C16)*('Inputs and method'!C8+C6*C16))/PI())/25.4)^2*C15^2/(6*(SQRT((('Inputs and method'!C7+C6*C16)*('Inputs and method'!C8+C6*C16))/PI())/25.4)+9*('Inputs and method'!C11/25.4)+10*(C6*C16/25.4))/1000 -> 76.284116 | D33: mH
A34: Series-pair resistance | C34: =2*C19 -> 99.935869 | D34: Ω
A35: Estimated series-pair inductance | C35: =2*C33 -> 152.56823 | D35: mH
A36: Relative induced signal / coil | C36: ='Inputs and method'!C23*C15/'Inputs and method'!C27 -> 2.4010816 | D36: × baseline
A37: Illustrative peak signal / coil | C37: =C36*'Inputs and method'!C22 -> 36.016224 | D37: µV peak
A38: Illustrative series-pair peak | C38: =2*C37 -> 72.032448 | D38: µV peak
A39: Johnson noise density / coil | C39: =SQRT(4*1.380649E-23*'Inputs and method'!C19*C19)*1000000000 -> 0.89941947 | D39: nV/√Hz
A40: Johnson noise density / pair | C40: =SQRT(4*1.380649E-23*'Inputs and method'!C19*C34)*1000000000 -> 1.2719712 | D40: nV/√Hz
A41: Relative coil-only SNR / coil | C41: =C36*SQRT('Inputs and method'!C21/C19) -> 0.76332048 | D41: × baseline
A42: Series-pair tuning capacitor | C42: =1/(2*PI()*'Inputs and method'!C18)^2/(C35/1000)*1000000000 -> 51.52847 | D42: nF
...

Sheet Inputs and method
A1: Inputs and calculation method
A2: Values in the input columns are editable. Heavy-build OD uses conservative published limits.
A3: Editable inputs
A4: Characteristic | B4: Polarization | C4: Sensing / coil | D4: Unit | E4: Basis or interpretation
A5: Wire length per spool | B5: 505 | C5: 1263 | D5: ft | E5: EMTEL listing; one polarization spool, one spool per sensing coil.
A6: Design insulated wire outside diameter | B6: 0.714 | C6: 0.462 | D6: mm | E6: Heavy-build maximum OD from published magnet-wire dimensions; confirm actual EMTEL insulated OD.
A7: Bobbin outer long dimension | B7: 146 | C7: 60 | D7: mm | E7: Approximate winding core dimensions.
A8: Bobbin outer short dimension | B8: 76 | C8: 60 | D8: mm | E8: Approximate winding core dimensions.
A9: Bobbin inner long dimension | B9: 140 | C9: 56 | D9: mm | E9: Approximate clear aperture.
A10: Bobbin inner short dimension | B10: 70 | C10: 56 | D10: mm | E10: Approximate clear aperture.
A11: Winding width | B11: 100 | C11: 100 | D11: mm | E11: Usable axial width; actual flanges may reduce this.
A12: Lead / winding margin | B12: 0.03 | C12: 0.03 | D12: fraction | E12: 3% of spool length held for leads, imperfect packing and variation.
A13: Copper resistance at 20 °C | B13: 16.14 | C13: 40.81 | D13: Ω/1000 ft | E13: Nominal AWG copper values; measure finished coils.
A14: Planned complete layers | B14: 2 | C14: 6 | D14: layers | E14: Used to calculate a partial final layer without circular formulas.
A15: Polarization current limit | B15: 3 | D15: A | E15: Prior design limit.
A16: Supply voltage ceiling | B16: 30 | D16: V | E16: Prior design limit.
A17: Assumed TVS voltage across coil during turn-off | B17: 68 | D17: V | E17: Illustrative effective TVS voltage across the coil during current decay; final value depends on the selected TVS and pulse current.
A18: Signal / tuning frequency | B18: 1795 | C18: 1795 | D18: Hz | E18: Approximate proton precession frequency.
A19: Noise temperature | B19: 293.15 | C19: 293.15 | D19: K | E19: 20 °C ambient; hot coil resistance/noise will increase.
A20: Earlier sensing baseline turns | C20: 590 | D20: turns/coil | E20: 20 AWG comparison design.
A21: Earlier sensing baseline resistance | C21: 5.05 | D21: Ω/coil | E21: 20 AWG comparison design.
A22: Earlier baseline peak signal | C22: 15 | D22: µV peak | E22: Illustrative prior assumption, not a measured signal.
A23: Earlier 1544-turn signal ratio | C23: 2.51 | D23: × | E23: Earlier area-adjusted estimate relative to 590-turn baseline.
A24: Polarization reference turns | B24: 342 | D24: turns | E24: Prior single-build geometric estimate.
A25: Polarization reference center field | B25: 8.92 | D25: mT | E25: Earlier finite rectangular-coil center-field estimate at 3 A.
A26: Polarization reference inductance | B26: 10.5 | D26: mH | E26: Earlier estimate at 342 turns.
A27: Sensing reference turns | C27: 1544 | D27: turns | E27: Earlier single-build geometric estimate.
A28: Legacy sensing reference inductance | C28: 41 | D28: mH | E28: Earlier per-coil estimate at 1544 turns. Retained for comparison; no longer used for the final sensing-coil inductance estimate.
A29: Sensing reference resistance | C29: 52 | D29: Ω | E29: Earlier estimate per coil at 1544 turns.
A30: Listing diameter (bare copper) | B30: 0.645 | C30: 0.404 | D30: mm | E30: EMTEL listing diameters match nominal bare AWG sizes; do not use as winding pitch.
A31: Method and limits
A32: Winding pitch | B32: Floor(winding width / insulated OD). Close packing assumed. Listing diameters are bare copper sizes.
A33: Turn length | B33: First turn uses outer bobbin dimensions plus one wire OD on each side; each added layer raises rectangular perimeter by 8 × OD.
A34: Turns | B34: Full-layer wire length is an arithmetic series; remaining usable wire forms a partial final layer.
A35: Resistance | B35: Used wire length × nominal 20 °C Ω/1000 ft; includes winding length but excludes connection/contact resistance.
A36: Field and inductance | B36: Polarization field and inductance are scaled from prior finite-geometry estimates. Sensing inductance uses a Wheeler multilayer-solenoid approximation with an equivalent circular radius derived from the mean wound rectangular area; measure the finished coils.
A37: Induced voltage | B37: Scaled from earlier area-adjusted 2.51× signal at 1544 turns. The 15 µV baseline is illustrative, not a measured absolute prediction.
A38: Noise and SNR | B38: Johnson density = √(4kTR). Coil-only SNR ratio = signal ratio × √(Rbaseline/Rcoil). Amplifier and environmental noise excluded.
A39: Resonance | B39: Pair assumes two equal series-aiding coils with negligible mutual coupling: Lpair = 2L, Rpair = 2R. C = 1/[(2πf)²Lpair].
A40: Q and ring-down | B40: Unloaded series Q = 2πfL/R. Voltage amplitude ring-down τ = 2Lpair/Rpair = Q/(πf); loading changes both.
...
